<?xml version="1.0"?>
<robot name="guyomi">
  <link name="base_link">
    <visual>
      <geometry>
        <cylinder length="0.0415" radius="0.075"/>
      </geometry>
      <material name="blue">
        <color rgba="0 0 .8 0.5"/>
      </material>
    </visual>
  </link>

  <link name="body_ballcaster">
    <visual>
      <geometry>
        <sphere radius="0.00259"/>
      </geometry>
      <material name="white">
        <color rgba="1 1 1 1"/>
      </material>
    </visual>
    <collision>
      <geometry>
        <sphere radius="0.00259"/>
      </geometry>
    </collision>
    <inertial>
      <mass value="0.1"/>
      <inertia ixx="1.0" ixy="0.0" ixz="0.0" iyy="1.0" iyz="0.0" izz="1.0"/>
    </inertial>
  </link>
  <joint name="body_ballcaster_joint" type="fixed">
    <parent link="base_link"/>
    <child link="body_ballcaster"/>
    <origin rpy="0 1.57075 0" xyz="0 0.05 -0.02075"/>
    <limit effort="100" velocity="100"/>
    <joint_properties damping="0.0" friction="0.0"/>
  </joint>

  <link name="right_wheel">
    <visual>
      <geometry>
        <cylinder length=".00525" radius="0.0259"/>
      </geometry>
      <material name="black">
        <color rgba="0 0 0 1"/>
      </material>
    </visual>
    <collision>
      <geometry>
        <cylinder length=".00525" radius="0.0259"/>
      </geometry>
    </collision>
    <inertial>
      <mass value="1"/>
      <inertia ixx="1.0" ixy="0.0" ixz="0.0" iyy="1.0" iyz="0.0" izz="1.0"/>
    </inertial>
  </link>

  <joint name="right_wheel_joint" type="continuous">
    <parent link="base_link"/>
    <child link="right_wheel"/>
    <axis xyz="0 0 1"/>
    <origin rpy="0 1.57075 0" xyz="0.05 -0.03 0"/>
    <limit effort="100" velocity="100"/>
    <joint_properties damping="0.0" friction="0.0"/>
  </joint>

  <link name="left_wheel">
    <visual>
      <geometry>
        <cylinder length=".00525" radius="0.0259"/>
      </geometry>
      <material name="black"/>
    </visual>
    <collision>
      <geometry>
        <cylinder length=".00525" radius="0.0259"/>
      </geometry>
    </collision>
    <inertial>
      <mass value="1"/>
      <inertia ixx="1.0" ixy="0.0" ixz="0.0" iyy="1.0" iyz="0.0" izz="1.0"/>
    </inertial>
  </link>
  <joint name="left_wheel_joint" type="continuous">
    <parent link="base_link"/>
    <child link="left_wheel"/>
    <axis xyz="0 0 1"/>
    <origin rpy="0 1.57075 0" xyz="-0.05 -0.03 0"/>
    <limit effort="100" velocity="100"/>
    <joint_properties damping="0.0" friction="0.0"/>
  </joint>
</robot>

